Traceback (most recent call last):
  File "c:\Users\Administrator\Desktop\python项目\1前端控制发邮件\test.py", line 37, in <module>
    dict=json.load(f)
  File "C:\ProgramData\Anaconda3\lib\json\__init__.py", line 293, in load
    return loads(fp.read(),
  File "C:\ProgramData\Anaconda3\lib\json\__init__.py", line 346, in loads
    return _default_decoder.decode(s)
  File "C:\ProgramData\Anaconda3\lib\json\decoder.py", line 337, in decode
    obj, end = self.raw_decode(s, idx=_w(s, 0).end())
  File "C:\ProgramData\Anaconda3\lib\json\decoder.py", line 355, in raw_decode
    raise JSONDecodeError("Expecting value", s, err.value) from None
json.decoder.JSONDecodeError: Expecting value: line 1 column 1 (char 0)
Traceback (most recent call last):
  File "c:\Users\Administrator\Desktop\python项目\日本爬商品评论\用requests测试亚马逊反爬强度.py", line 37, in <module>
    dict=json.load(f)
  File "C:\ProgramData\Anaconda3\lib\json\__init__.py", line 293, in load
    return loads(fp.read(),
  File "C:\ProgramData\Anaconda3\lib\json\__init__.py", line 346, in loads
    return _default_decoder.decode(s)
  File "C:\ProgramData\Anaconda3\lib\json\decoder.py", line 337, in decode
    obj, end = self.raw_decode(s, idx=_w(s, 0).end())
  File "C:\ProgramData\Anaconda3\lib\json\decoder.py", line 355, in raw_decode
    raise JSONDecodeError("Expecting value", s, err.value) from None
json.decoder.JSONDecodeError: Expecting value: line 1 column 1 (char 0)
Traceback (most recent call last):
  File "c:\Users\Administrator\Desktop\python项目\日本爬商品评论\用requests测试亚马逊反爬强度.py", line 70, in <module>
    with open("asins.json","r",encoding="utf-8") as f:
FileNotFoundError: [Errno 2] No such file or directory: 'asins.json'
Traceback (most recent call last):
  File "c:\Users\Administrator\Desktop\python项目\日本爬商品评论\用requests测试亚马逊反爬强度.py", line 37, in <module>
    dict=json.load(f)
  File "C:\ProgramData\Anaconda3\lib\json\__init__.py", line 293, in load
    return loads(fp.read(),
  File "C:\ProgramData\Anaconda3\lib\json\__init__.py", line 346, in loads
    return _default_decoder.decode(s)
  File "C:\ProgramData\Anaconda3\lib\json\decoder.py", line 337, in decode
    obj, end = self.raw_decode(s, idx=_w(s, 0).end())
  File "C:\ProgramData\Anaconda3\lib\json\decoder.py", line 355, in raw_decode
    raise JSONDecodeError("Expecting value", s, err.value) from None
json.decoder.JSONDecodeError: Expecting value: line 1 column 1 (char 0)
Traceback (most recent call last):
  File "c:\Users\Administrator\Desktop\python项目\日本爬商品评论\用requests测试亚马逊反爬强度.py", line 70, in <module>
    with open("asins.json","r",encoding="utf-8") as f:
FileNotFoundError: [Errno 2] No such file or directory: 'asins.json'
Traceback (most recent call last):
  File "c:\Users\Administrator\Desktop\python项目\日本爬商品评论\用requests测试亚马逊反爬强度.py", line 70, in <module>
    with open("asins.json","r",encoding="utf-8") as f:
FileNotFoundError: [Errno 2] No such file or directory: 'asins.json'
Traceback (most recent call last):
  File "c:\Users\Administrator\Desktop\python项目\1前端控制发邮件\test.py", line 37, in <module>
    dict=json.load(f)
  File "C:\ProgramData\Anaconda3\lib\json\__init__.py", line 293, in load
    return loads(fp.read(),
  File "C:\ProgramData\Anaconda3\lib\json\__init__.py", line 346, in loads
    return _default_decoder.decode(s)
  File "C:\ProgramData\Anaconda3\lib\json\decoder.py", line 337, in decode
    obj, end = self.raw_decode(s, idx=_w(s, 0).end())
  File "C:\ProgramData\Anaconda3\lib\json\decoder.py", line 355, in raw_decode
    raise JSONDecodeError("Expecting value", s, err.value) from None
json.decoder.JSONDecodeError: Expecting value: line 1 column 1 (char 0)
Traceback (most recent call last):
  File "C:\ProgramData\Anaconda3\lib\site-packages\urllib3\connectionpool.py", line 696, in urlopen
    self._prepare_proxy(conn)
  File "C:\ProgramData\Anaconda3\lib\site-packages\urllib3\connectionpool.py", line 964, in _prepare_proxy
    conn.connect()
  File "C:\ProgramData\Anaconda3\lib\site-packages\urllib3\connection.py", line 364, in connect
    conn = self._connect_tls_proxy(hostname, conn)
  File "C:\ProgramData\Anaconda3\lib\site-packages\urllib3\connection.py", line 501, in _connect_tls_proxy
    socket = ssl_wrap_socket(
  File "C:\ProgramData\Anaconda3\lib\site-packages\urllib3\util\ssl_.py", line 453, in ssl_wrap_socket
    ssl_sock = _ssl_wrap_socket_impl(sock, context, tls_in_tls)
  File "C:\ProgramData\Anaconda3\lib\site-packages\urllib3\util\ssl_.py", line 495, in _ssl_wrap_socket_impl
    return ssl_context.wrap_socket(sock)
  File "C:\ProgramData\Anaconda3\lib\ssl.py", line 500, in wrap_socket
    return self.sslsocket_class._create(
  File "C:\ProgramData\Anaconda3\lib\ssl.py", line 1040, in _create
    self.do_handshake()
  File "C:\ProgramData\Anaconda3\lib\ssl.py", line 1309, in do_handshake
    self._sslobj.do_handshake()
ssl.SSLEOFError: EOF occurred in violation of protocol (_ssl.c:1129)

During handling of the above exception, another exception occurred:

Traceback (most recent call last):
  File "C:\ProgramData\Anaconda3\lib\site-packages\requests\adapters.py", line 439, in send
    resp = conn.urlopen(
  File "C:\ProgramData\Anaconda3\lib\site-packages\urllib3\connectionpool.py", line 755, in urlopen
    retries = retries.increment(
  File "C:\ProgramData\Anaconda3\lib\site-packages\urllib3\util\retry.py", line 574, in increment
    raise MaxRetryError(_pool, url, error or ResponseError(cause))
urllib3.exceptions.MaxRetryError: HTTPSConnectionPool(host='www.amazon.com', port=443): Max retries exceeded with url: /profilewidget/bio/amzn1.account.AG5YCWXZZH4XZFQSEAOPVERQ3NYQ?view=visitor (Caused by SSLError(SSLEOFError(8, 'EOF occurred in violation of protocol (_ssl.c:1129)')))

During handling of the above exception, another exception occurred:

Traceback (most recent call last):
  File "c:\Users\Administrator\Desktop\python项目\1前端控制发邮件\test.py", line 80, in <module>
    page=requests.get(url=url,headers=headers)
  File "C:\ProgramData\Anaconda3\lib\site-packages\requests\api.py", line 75, in get
    return request('get', url, params=params, **kwargs)
  File "C:\ProgramData\Anaconda3\lib\site-packages\requests\api.py", line 61, in request
    return session.request(method=method, url=url, **kwargs)
  File "C:\ProgramData\Anaconda3\lib\site-packages\requests\sessions.py", line 542, in request
    resp = self.send(prep, **send_kwargs)
  File "C:\ProgramData\Anaconda3\lib\site-packages\requests\sessions.py", line 655, in send
    r = adapter.send(request, **kwargs)
  File "C:\ProgramData\Anaconda3\lib\site-packages\requests\adapters.py", line 514, in send
    raise SSLError(e, request=request)
requests.exceptions.SSLError: HTTPSConnectionPool(host='www.amazon.com', port=443): Max retries exceeded with url: /profilewidget/bio/amzn1.account.AG5YCWXZZH4XZFQSEAOPVERQ3NYQ?view=visitor (Caused by SSLError(SSLEOFError(8, 'EOF occurred in violation of protocol (_ssl.c:1129)')))
